2025-05-31 23:24:59,281 - bot_logger - ERROR - Error starting bot: The asyncio extension requires an async driver to be used. The loaded 'psycopg2' is not async.
Traceback (most recent call last):
  File "/home/hesam/Desktop/appleid_bot/main.py", line 68, in main
    session_maker = await init_db(config.db.database_url)
                          ^^^^^^^^^^^^^^^^^^^^^^^^^^^^^^^
  File "/home/hesam/Desktop/appleid_bot/app/database.py", line 233, in init_db
    engine = create_async_engine(database_url, echo=False)
             ^^^^^^^^^^^^^^^^^^^^^^^^^^^^^^^^^^^^^^^^^^^^^
  File "/home/hesam/Desktop/appleid_bot/venv/lib/python3.12/site-packages/sqlalchemy/ext/asyncio/engine.py", line 121, in create_async_engine
    return AsyncEngine(sync_engine)
           ^^^^^^^^^^^^^^^^^^^^^^^^
  File "/home/hesam/Desktop/appleid_bot/venv/lib/python3.12/site-packages/sqlalchemy/ext/asyncio/engine.py", line 1033, in __init__
    raise exc.InvalidRequestError(
sqlalchemy.exc.InvalidRequestError: The asyncio extension requires an async driver to be used. The loaded 'psycopg2' is not async.
2025-05-31 23:30:35,487 - bot_logger - ERROR - Error starting bot: The asyncio extension requires an async driver to be used. The loaded 'psycopg2' is not async.
Traceback (most recent call last):
  File "/home/hesam/Desktop/appleid_bot/main.py", line 26, in main
    session_pool = await init_db(config.db.database_url)
                   ^^^^^^^^^^^^^^^^^^^^^^^^^^^^^^^^^^^^^
  File "/home/hesam/Desktop/appleid_bot/app/database.py", line 246, in init_db
    engine = create_async_engine(
             ^^^^^^^^^^^^^^^^^^^^
  File "/home/hesam/Desktop/appleid_bot/venv/lib/python3.12/site-packages/sqlalchemy/ext/asyncio/engine.py", line 121, in create_async_engine
    return AsyncEngine(sync_engine)
           ^^^^^^^^^^^^^^^^^^^^^^^^
  File "/home/hesam/Desktop/appleid_bot/venv/lib/python3.12/site-packages/sqlalchemy/ext/asyncio/engine.py", line 1033, in __init__
    raise exc.InvalidRequestError(
sqlalchemy.exc.InvalidRequestError: The asyncio extension requires an async driver to be used. The loaded 'psycopg2' is not async.
2025-05-31 23:32:54,799 - bot_logger - ERROR - Error starting bot: [Errno 111] Connect call failed ('127.0.0.1', 5432)
Traceback (most recent call last):
  File "/home/hesam/Desktop/appleid_bot/main.py", line 26, in main
    session_pool = await init_db(config.db.database_url)
                   ^^^^^^^^^^^^^^^^^^^^^^^^^^^^^^^^^^^^^
  File "/home/hesam/Desktop/appleid_bot/app/database.py", line 254, in init_db
    async with engine.begin() as conn:
  File "/usr/lib/python3.12/contextlib.py", line 210, in __aenter__
    return await anext(self.gen)
           ^^^^^^^^^^^^^^^^^^^^^
  File "/home/hesam/Desktop/appleid_bot/venv/lib/python3.12/site-packages/sqlalchemy/ext/asyncio/engine.py", line 1066, in begin
    async with conn:
  File "/home/hesam/Desktop/appleid_bot/venv/lib/python3.12/site-packages/sqlalchemy/ext/asyncio/base.py", line 121, in __aenter__
    return await self.start(is_ctxmanager=True)
           ^^^^^^^^^^^^^^^^^^^^^^^^^^^^^^^^^^^^
  File "/home/hesam/Desktop/appleid_bot/venv/lib/python3.12/site-packages/sqlalchemy/ext/asyncio/engine.py", line 274, in start
    await greenlet_spawn(self.sync_engine.connect)
  File "/home/hesam/Desktop/appleid_bot/venv/lib/python3.12/site-packages/sqlalchemy/util/_concurrency_py3k.py", line 201, in greenlet_spawn
    result = context.throw(*sys.exc_info())
             ^^^^^^^^^^^^^^^^^^^^^^^^^^^^^^
  File "/home/hesam/Desktop/appleid_bot/venv/lib/python3.12/site-packages/sqlalchemy/engine/base.py", line 3273, in connect
    return self._connection_cls(self)
           ^^^^^^^^^^^^^^^^^^^^^^^^^^
  File "/home/hesam/Desktop/appleid_bot/venv/lib/python3.12/site-packages/sqlalchemy/engine/base.py", line 145, in __init__
    self._dbapi_connection = engine.raw_connection()
                             ^^^^^^^^^^^^^^^^^^^^^^^
  File "/home/hesam/Desktop/appleid_bot/venv/lib/python3.12/site-packages/sqlalchemy/engine/base.py", line 3297, in raw_connection
    return self.pool.connect()
           ^^^^^^^^^^^^^^^^^^^
  File "/home/hesam/Desktop/appleid_bot/venv/lib/python3.12/site-packages/sqlalchemy/pool/base.py", line 449, in connect
    return _ConnectionFairy._checkout(self)
           ^^^^^^^^^^^^^^^^^^^^^^^^^^^^^^^^
  File "/home/hesam/Desktop/appleid_bot/venv/lib/python3.12/site-packages/sqlalchemy/pool/base.py", line 1264, in _checkout
    fairy = _ConnectionRecord.checkout(pool)
            ^^^^^^^^^^^^^^^^^^^^^^^^^^^^^^^^
  File "/home/hesam/Desktop/appleid_bot/venv/lib/python3.12/site-packages/sqlalchemy/pool/base.py", line 713, in checkout
    rec = pool._do_get()
          ^^^^^^^^^^^^^^
  File "/home/hesam/Desktop/appleid_bot/venv/lib/python3.12/site-packages/sqlalchemy/pool/impl.py", line 179, in _do_get
    with util.safe_reraise():
  File "/home/hesam/Desktop/appleid_bot/venv/lib/python3.12/site-packages/sqlalchemy/util/langhelpers.py", line 224, in __exit__
    raise exc_value.with_traceback(exc_tb)
  File "/home/hesam/Desktop/appleid_bot/venv/lib/python3.12/site-packages/sqlalchemy/pool/impl.py", line 177, in _do_get
    return self._create_connection()
           ^^^^^^^^^^^^^^^^^^^^^^^^^
  File "/home/hesam/Desktop/appleid_bot/venv/lib/python3.12/site-packages/sqlalchemy/pool/base.py", line 390, in _create_connection
    return _ConnectionRecord(self)
           ^^^^^^^^^^^^^^^^^^^^^^^
  File "/home/hesam/Desktop/appleid_bot/venv/lib/python3.12/site-packages/sqlalchemy/pool/base.py", line 675, in __init__
    self.__connect()
  File "/home/hesam/Desktop/appleid_bot/venv/lib/python3.12/site-packages/sqlalchemy/pool/base.py", line 901, in __connect
    with util.safe_reraise():
  File "/home/hesam/Desktop/appleid_bot/venv/lib/python3.12/site-packages/sqlalchemy/util/langhelpers.py", line 224, in __exit__
    raise exc_value.with_traceback(exc_tb)
  File "/home/hesam/Desktop/appleid_bot/venv/lib/python3.12/site-packages/sqlalchemy/pool/base.py", line 897, in __connect
    self.dbapi_connection = connection = pool._invoke_creator(self)
                                         ^^^^^^^^^^^^^^^^^^^^^^^^^^
  File "/home/hesam/Desktop/appleid_bot/venv/lib/python3.12/site-packages/sqlalchemy/engine/create.py", line 646, in connect
    return dialect.connect(*cargs, **cparams)
           ^^^^^^^^^^^^^^^^^^^^^^^^^^^^^^^^^^
  File "/home/hesam/Desktop/appleid_bot/venv/lib/python3.12/site-packages/sqlalchemy/engine/default.py", line 625, in connect
    return self.loaded_dbapi.connect(*cargs, **cparams)  # type: ignore[no-any-return]  # NOQA: E501
           ^^^^^^^^^^^^^^^^^^^^^^^^^^^^^^^^^^^^^^^^^^^^
  File "/home/hesam/Desktop/appleid_bot/venv/lib/python3.12/site-packages/sqlalchemy/dialects/postgresql/asyncpg.py", line 961, in connect
    await_only(creator_fn(*arg, **kw)),
    ^^^^^^^^^^^^^^^^^^^^^^^^^^^^^^^^^^
  File "/home/hesam/Desktop/appleid_bot/venv/lib/python3.12/site-packages/sqlalchemy/util/_concurrency_py3k.py", line 132, in await_only
    return current.parent.switch(awaitable)  # type: ignore[no-any-return,attr-defined] # noqa: E501
           ^^^^^^^^^^^^^^^^^^^^^^^^^^^^^^^^
  File "/home/hesam/Desktop/appleid_bot/venv/lib/python3.12/site-packages/sqlalchemy/util/_concurrency_py3k.py", line 196, in greenlet_spawn
    value = await result
            ^^^^^^^^^^^^
  File "/home/hesam/Desktop/appleid_bot/venv/lib/python3.12/site-packages/asyncpg/connection.py", line 2421, in connect
    return await connect_utils._connect(
           ^^^^^^^^^^^^^^^^^^^^^^^^^^^^^
  File "/home/hesam/Desktop/appleid_bot/venv/lib/python3.12/site-packages/asyncpg/connect_utils.py", line 1075, in _connect
    raise last_error or exceptions.TargetServerAttributeNotMatched(
  File "/home/hesam/Desktop/appleid_bot/venv/lib/python3.12/site-packages/asyncpg/connect_utils.py", line 1049, in _connect
    conn = await _connect_addr(
           ^^^^^^^^^^^^^^^^^^^^
  File "/home/hesam/Desktop/appleid_bot/venv/lib/python3.12/site-packages/asyncpg/connect_utils.py", line 886, in _connect_addr
    return await __connect_addr(params, True, *args)
           ^^^^^^^^^^^^^^^^^^^^^^^^^^^^^^^^^^^^^^^^^
  File "/home/hesam/Desktop/appleid_bot/venv/lib/python3.12/site-packages/asyncpg/connect_utils.py", line 931, in __connect_addr
    tr, pr = await connector
             ^^^^^^^^^^^^^^^
  File "/home/hesam/Desktop/appleid_bot/venv/lib/python3.12/site-packages/asyncpg/connect_utils.py", line 802, in _create_ssl_connection
    tr, pr = await loop.create_connection(
             ^^^^^^^^^^^^^^^^^^^^^^^^^^^^^
  File "/usr/lib/python3.12/asyncio/base_events.py", line 1122, in create_connection
    raise exceptions[0]
  File "/usr/lib/python3.12/asyncio/base_events.py", line 1104, in create_connection
    sock = await self._connect_sock(
           ^^^^^^^^^^^^^^^^^^^^^^^^^
  File "/usr/lib/python3.12/asyncio/base_events.py", line 1007, in _connect_sock
    await self.sock_connect(sock, address)
  File "/usr/lib/python3.12/asyncio/selector_events.py", line 651, in sock_connect
    return await fut
           ^^^^^^^^^
  File "/usr/lib/python3.12/asyncio/selector_events.py", line 691, in _sock_connect_cb
    raise OSError(err, f'Connect call failed {address}')
ConnectionRefusedError: [Errno 111] Connect call failed ('127.0.0.1', 5432)
2025-05-31 23:37:59,476 - bot_logger - ERROR - Error starting bot: password authentication failed for user "hesam"
Traceback (most recent call last):
  File "/home/hesam/Desktop/appleid_bot/main.py", line 26, in main
    session_pool = await init_db(config.db.database_url)
                   ^^^^^^^^^^^^^^^^^^^^^^^^^^^^^^^^^^^^^
  File "/home/hesam/Desktop/appleid_bot/app/database.py", line 254, in init_db
    async with engine.begin() as conn:
  File "/usr/lib/python3.12/contextlib.py", line 210, in __aenter__
    return await anext(self.gen)
           ^^^^^^^^^^^^^^^^^^^^^
  File "/home/hesam/Desktop/appleid_bot/venv/lib/python3.12/site-packages/sqlalchemy/ext/asyncio/engine.py", line 1066, in begin
    async with conn:
  File "/home/hesam/Desktop/appleid_bot/venv/lib/python3.12/site-packages/sqlalchemy/ext/asyncio/base.py", line 121, in __aenter__
    return await self.start(is_ctxmanager=True)
           ^^^^^^^^^^^^^^^^^^^^^^^^^^^^^^^^^^^^
  File "/home/hesam/Desktop/appleid_bot/venv/lib/python3.12/site-packages/sqlalchemy/ext/asyncio/engine.py", line 274, in start
    await greenlet_spawn(self.sync_engine.connect)
  File "/home/hesam/Desktop/appleid_bot/venv/lib/python3.12/site-packages/sqlalchemy/util/_concurrency_py3k.py", line 201, in greenlet_spawn
    result = context.throw(*sys.exc_info())
             ^^^^^^^^^^^^^^^^^^^^^^^^^^^^^^
  File "/home/hesam/Desktop/appleid_bot/venv/lib/python3.12/site-packages/sqlalchemy/engine/base.py", line 3273, in connect
    return self._connection_cls(self)
           ^^^^^^^^^^^^^^^^^^^^^^^^^^
  File "/home/hesam/Desktop/appleid_bot/venv/lib/python3.12/site-packages/sqlalchemy/engine/base.py", line 145, in __init__
    self._dbapi_connection = engine.raw_connection()
                             ^^^^^^^^^^^^^^^^^^^^^^^
  File "/home/hesam/Desktop/appleid_bot/venv/lib/python3.12/site-packages/sqlalchemy/engine/base.py", line 3297, in raw_connection
    return self.pool.connect()
           ^^^^^^^^^^^^^^^^^^^
  File "/home/hesam/Desktop/appleid_bot/venv/lib/python3.12/site-packages/sqlalchemy/pool/base.py", line 449, in connect
    return _ConnectionFairy._checkout(self)
           ^^^^^^^^^^^^^^^^^^^^^^^^^^^^^^^^
  File "/home/hesam/Desktop/appleid_bot/venv/lib/python3.12/site-packages/sqlalchemy/pool/base.py", line 1264, in _checkout
    fairy = _ConnectionRecord.checkout(pool)
            ^^^^^^^^^^^^^^^^^^^^^^^^^^^^^^^^
  File "/home/hesam/Desktop/appleid_bot/venv/lib/python3.12/site-packages/sqlalchemy/pool/base.py", line 713, in checkout
    rec = pool._do_get()
          ^^^^^^^^^^^^^^
  File "/home/hesam/Desktop/appleid_bot/venv/lib/python3.12/site-packages/sqlalchemy/pool/impl.py", line 179, in _do_get
    with util.safe_reraise():
  File "/home/hesam/Desktop/appleid_bot/venv/lib/python3.12/site-packages/sqlalchemy/util/langhelpers.py", line 224, in __exit__
    raise exc_value.with_traceback(exc_tb)
  File "/home/hesam/Desktop/appleid_bot/venv/lib/python3.12/site-packages/sqlalchemy/pool/impl.py", line 177, in _do_get
    return self._create_connection()
           ^^^^^^^^^^^^^^^^^^^^^^^^^
  File "/home/hesam/Desktop/appleid_bot/venv/lib/python3.12/site-packages/sqlalchemy/pool/base.py", line 390, in _create_connection
    return _ConnectionRecord(self)
           ^^^^^^^^^^^^^^^^^^^^^^^
  File "/home/hesam/Desktop/appleid_bot/venv/lib/python3.12/site-packages/sqlalchemy/pool/base.py", line 675, in __init__
    self.__connect()
  File "/home/hesam/Desktop/appleid_bot/venv/lib/python3.12/site-packages/sqlalchemy/pool/base.py", line 901, in __connect
    with util.safe_reraise():
  File "/home/hesam/Desktop/appleid_bot/venv/lib/python3.12/site-packages/sqlalchemy/util/langhelpers.py", line 224, in __exit__
    raise exc_value.with_traceback(exc_tb)
  File "/home/hesam/Desktop/appleid_bot/venv/lib/python3.12/site-packages/sqlalchemy/pool/base.py", line 897, in __connect
    self.dbapi_connection = connection = pool._invoke_creator(self)
                                         ^^^^^^^^^^^^^^^^^^^^^^^^^^
  File "/home/hesam/Desktop/appleid_bot/venv/lib/python3.12/site-packages/sqlalchemy/engine/create.py", line 646, in connect
    return dialect.connect(*cargs, **cparams)
           ^^^^^^^^^^^^^^^^^^^^^^^^^^^^^^^^^^
  File "/home/hesam/Desktop/appleid_bot/venv/lib/python3.12/site-packages/sqlalchemy/engine/default.py", line 625, in connect
    return self.loaded_dbapi.connect(*cargs, **cparams)  # type: ignore[no-any-return]  # NOQA: E501
           ^^^^^^^^^^^^^^^^^^^^^^^^^^^^^^^^^^^^^^^^^^^^
  File "/home/hesam/Desktop/appleid_bot/venv/lib/python3.12/site-packages/sqlalchemy/dialects/postgresql/asyncpg.py", line 961, in connect
    await_only(creator_fn(*arg, **kw)),
    ^^^^^^^^^^^^^^^^^^^^^^^^^^^^^^^^^^
  File "/home/hesam/Desktop/appleid_bot/venv/lib/python3.12/site-packages/sqlalchemy/util/_concurrency_py3k.py", line 132, in await_only
    return current.parent.switch(awaitable)  # type: ignore[no-any-return,attr-defined] # noqa: E501
           ^^^^^^^^^^^^^^^^^^^^^^^^^^^^^^^^
  File "/home/hesam/Desktop/appleid_bot/venv/lib/python3.12/site-packages/sqlalchemy/util/_concurrency_py3k.py", line 196, in greenlet_spawn
    value = await result
            ^^^^^^^^^^^^
  File "/home/hesam/Desktop/appleid_bot/venv/lib/python3.12/site-packages/asyncpg/connection.py", line 2421, in connect
    return await connect_utils._connect(
           ^^^^^^^^^^^^^^^^^^^^^^^^^^^^^
  File "/home/hesam/Desktop/appleid_bot/venv/lib/python3.12/site-packages/asyncpg/connect_utils.py", line 1049, in _connect
    conn = await _connect_addr(
           ^^^^^^^^^^^^^^^^^^^^
  File "/home/hesam/Desktop/appleid_bot/venv/lib/python3.12/site-packages/asyncpg/connect_utils.py", line 891, in _connect_addr
    return await __connect_addr(params_retry, False, *args)
           ^^^^^^^^^^^^^^^^^^^^^^^^^^^^^^^^^^^^^^^^^^^^^^^^
  File "/home/hesam/Desktop/appleid_bot/venv/lib/python3.12/site-packages/asyncpg/connect_utils.py", line 934, in __connect_addr
    await connected
asyncpg.exceptions.InvalidPasswordError: password authentication failed for user "hesam"
